<?xml version="1.0" ?>
<!-- =================================================================================== -->
<!-- |    This document was autogenerated by xacro from urdf/SUSTAINA-OP2.xacro        | -->
<!-- |    EDITING THIS FILE BY HAND IS NOT RECOMMENDED                                 | -->
<!-- =================================================================================== -->
<robot xmlns:xacro="http://www.ros.org/wiki/xacro" name="SUSTAINA-OP2">
  <material name="silver">
    <color rgba="0.700 0.700 0.700 1.000"/>
  </material>
  <transmission name="Head_Yaw_tran">
    <type>transmission_interface/SimpleTransmission</type>
    <joint name="Head_Yaw">
      <hardwareInterface>hardware_interface/EffortJointInterface</hardwareInterface>
    </joint>
    <actuator name="Head_Yaw_actr">
      <hardwareInterface>hardware_interface/EffortJointInterface</hardwareInterface>
      <mechanicalReduction>1</mechanicalReduction>
    </actuator>
  </transmission>
  <transmission name="LeftShoulder_Pitch_tran">
    <type>transmission_interface/SimpleTransmission</type>
    <joint name="LeftShoulder_Pitch">
      <hardwareInterface>hardware_interface/EffortJointInterface</hardwareInterface>
    </joint>
    <actuator name="LeftShoulder_Pitch_actr">
      <hardwareInterface>hardware_interface/EffortJointInterface</hardwareInterface>
      <mechanicalReduction>1</mechanicalReduction>
    </actuator>
  </transmission>
  <transmission name="RightShoulder_Pitch_tran">
    <type>transmission_interface/SimpleTransmission</type>
    <joint name="RightShoulder_Pitch">
      <hardwareInterface>hardware_interface/EffortJointInterface</hardwareInterface>
    </joint>
    <actuator name="RightShoulder_Pitch_actr">
      <hardwareInterface>hardware_interface/EffortJointInterface</hardwareInterface>
      <mechanicalReduction>1</mechanicalReduction>
    </actuator>
  </transmission>
  <transmission name="LeftShoulder_Roll_tran">
    <type>transmission_interface/SimpleTransmission</type>
    <joint name="LeftShoulder_Roll">
      <hardwareInterface>hardware_interface/EffortJointInterface</hardwareInterface>
    </joint>
    <actuator name="LeftShoulder_Roll_actr">
      <hardwareInterface>hardware_interface/EffortJointInterface</hardwareInterface>
      <mechanicalReduction>1</mechanicalReduction>
    </actuator>
  </transmission>
  <transmission name="LeftElbow_Pitch_tran">
    <type>transmission_interface/SimpleTransmission</type>
    <joint name="LeftElbow_Pitch">
      <hardwareInterface>hardware_interface/EffortJointInterface</hardwareInterface>
    </joint>
    <actuator name="LeftElbow_Pitch_actr">
      <hardwareInterface>hardware_interface/EffortJointInterface</hardwareInterface>
      <mechanicalReduction>1</mechanicalReduction>
    </actuator>
  </transmission>
  <transmission name="RightShoulder_Roll_tran">
    <type>transmission_interface/SimpleTransmission</type>
    <joint name="RightShoulder_Roll">
      <hardwareInterface>hardware_interface/EffortJointInterface</hardwareInterface>
    </joint>
    <actuator name="RightShoulder_Roll_actr">
      <hardwareInterface>hardware_interface/EffortJointInterface</hardwareInterface>
      <mechanicalReduction>1</mechanicalReduction>
    </actuator>
  </transmission>
  <transmission name="RightElbow_Pitch_tran">
    <type>transmission_interface/SimpleTransmission</type>
    <joint name="RightElbow_Pitch">
      <hardwareInterface>hardware_interface/EffortJointInterface</hardwareInterface>
    </joint>
    <actuator name="RightElbow_Pitch_actr">
      <hardwareInterface>hardware_interface/EffortJointInterface</hardwareInterface>
      <mechanicalReduction>1</mechanicalReduction>
    </actuator>
  </transmission>
  <transmission name="LeftHip_Yaw_tran">
    <type>transmission_interface/SimpleTransmission</type>
    <joint name="LeftHip_Yaw">
      <hardwareInterface>hardware_interface/EffortJointInterface</hardwareInterface>
    </joint>
    <actuator name="LeftHip_Yaw_actr">
      <hardwareInterface>hardware_interface/EffortJointInterface</hardwareInterface>
      <mechanicalReduction>1</mechanicalReduction>
    </actuator>
  </transmission>
  <transmission name="RightHip_Yaw_tran">
    <type>transmission_interface/SimpleTransmission</type>
    <joint name="RightHip_Yaw">
      <hardwareInterface>hardware_interface/EffortJointInterface</hardwareInterface>
    </joint>
    <actuator name="RightHip_Yaw_actr">
      <hardwareInterface>hardware_interface/EffortJointInterface</hardwareInterface>
      <mechanicalReduction>1</mechanicalReduction>
    </actuator>
  </transmission>
  <transmission name="LeftHip_Roll_tran">
    <type>transmission_interface/SimpleTransmission</type>
    <joint name="LeftHip_Roll">
      <hardwareInterface>hardware_interface/EffortJointInterface</hardwareInterface>
    </joint>
    <actuator name="LeftHip_Roll_actr">
      <hardwareInterface>hardware_interface/EffortJointInterface</hardwareInterface>
      <mechanicalReduction>1</mechanicalReduction>
    </actuator>
  </transmission>
  <transmission name="RightHip_Roll_tran">
    <type>transmission_interface/SimpleTransmission</type>
    <joint name="RightHip_Roll">
      <hardwareInterface>hardware_interface/EffortJointInterface</hardwareInterface>
    </joint>
    <actuator name="RightHip_Roll_actr">
      <hardwareInterface>hardware_interface/EffortJointInterface</hardwareInterface>
      <mechanicalReduction>1</mechanicalReduction>
    </actuator>
  </transmission>
  <transmission name="LeftHip_MimicPitch_tran">
    <type>transmission_interface/SimpleTransmission</type>
    <joint name="LeftHip_MimicPitch">
      <hardwareInterface>hardware_interface/EffortJointInterface</hardwareInterface>
    </joint>
    <actuator name="LeftHip_MimicPitch_actr">
      <hardwareInterface>hardware_interface/EffortJointInterface</hardwareInterface>
      <mechanicalReduction>1</mechanicalReduction>
    </actuator>
  </transmission>
  <transmission name="RightHip_MimicPitch_tran">
    <type>transmission_interface/SimpleTransmission</type>
    <joint name="RightHip_MimicPitch">
      <hardwareInterface>hardware_interface/EffortJointInterface</hardwareInterface>
    </joint>
    <actuator name="RightHip_MimicPitch_actr">
      <hardwareInterface>hardware_interface/EffortJointInterface</hardwareInterface>
      <mechanicalReduction>1</mechanicalReduction>
    </actuator>
  </transmission>
  <transmission name="LeftHipBackLink_tran">
    <type>transmission_interface/SimpleTransmission</type>
    <joint name="LeftHipBackLink">
      <hardwareInterface>hardware_interface/EffortJointInterface</hardwareInterface>
    </joint>
    <actuator name="LeftHipBackLink_actr">
      <hardwareInterface>hardware_interface/EffortJointInterface</hardwareInterface>
      <mechanicalReduction>1</mechanicalReduction>
    </actuator>
  </transmission>
  <transmission name="RightHipBackLink_tran">
    <type>transmission_interface/SimpleTransmission</type>
    <joint name="RightHipBackLink">
      <hardwareInterface>hardware_interface/EffortJointInterface</hardwareInterface>
    </joint>
    <actuator name="RightHipBackLink_actr">
      <hardwareInterface>hardware_interface/EffortJointInterface</hardwareInterface>
      <mechanicalReduction>1</mechanicalReduction>
    </actuator>
  </transmission>
  <transmission name="LeftUpperKnee_Pitch_tran">
    <type>transmission_interface/SimpleTransmission</type>
    <joint name="LeftUpperKnee_Pitch">
      <hardwareInterface>hardware_interface/EffortJointInterface</hardwareInterface>
    </joint>
    <actuator name="LeftUpperKnee_Pitch_actr">
      <hardwareInterface>hardware_interface/EffortJointInterface</hardwareInterface>
      <mechanicalReduction>1</mechanicalReduction>
    </actuator>
  </transmission>
  <transmission name="RightUpperKne_Pitch_tran">
    <type>transmission_interface/SimpleTransmission</type>
    <joint name="RightUpperKne_Pitch">
      <hardwareInterface>hardware_interface/EffortJointInterface</hardwareInterface>
    </joint>
    <actuator name="RightUpperKne_Pitch_actr">
      <hardwareInterface>hardware_interface/EffortJointInterface</hardwareInterface>
      <mechanicalReduction>1</mechanicalReduction>
    </actuator>
  </transmission>
  <transmission name="LeftUpperKnee_MimicPitch_tran">
    <type>transmission_interface/SimpleTransmission</type>
    <joint name="LeftUpperKnee_MimicPitch">
      <hardwareInterface>hardware_interface/EffortJointInterface</hardwareInterface>
    </joint>
    <actuator name="LeftUpperKnee_MimicPitch_actr">
      <hardwareInterface>hardware_interface/EffortJointInterface</hardwareInterface>
      <mechanicalReduction>1</mechanicalReduction>
    </actuator>
  </transmission>
  <transmission name="RightUpperKnee_MimicPitch_tran">
    <type>transmission_interface/SimpleTransmission</type>
    <joint name="RightUpperKnee_MimicPitch">
      <hardwareInterface>hardware_interface/EffortJointInterface</hardwareInterface>
    </joint>
    <actuator name="RightUpperKnee_MimicPitch_actr">
      <hardwareInterface>hardware_interface/EffortJointInterface</hardwareInterface>
      <mechanicalReduction>1</mechanicalReduction>
    </actuator>
  </transmission>
  <transmission name="LeftLowerKnee_Pitch_tran">
    <type>transmission_interface/SimpleTransmission</type>
    <joint name="LeftLowerKnee_Pitch">
      <hardwareInterface>hardware_interface/EffortJointInterface</hardwareInterface>
    </joint>
    <actuator name="LeftLowerKnee_Pitch_actr">
      <hardwareInterface>hardware_interface/EffortJointInterface</hardwareInterface>
      <mechanicalReduction>1</mechanicalReduction>
    </actuator>
  </transmission>
  <transmission name="RightLowerKnee_Pitch_tran">
    <type>transmission_interface/SimpleTransmission</type>
    <joint name="RightLowerKnee_Pitch">
      <hardwareInterface>hardware_interface/EffortJointInterface</hardwareInterface>
    </joint>
    <actuator name="RightLowerKnee_Pitch_actr">
      <hardwareInterface>hardware_interface/EffortJointInterface</hardwareInterface>
      <mechanicalReduction>1</mechanicalReduction>
    </actuator>
  </transmission>
  <transmission name="LeftLowerKnee_MimicPitch_tran">
    <type>transmission_interface/SimpleTransmission</type>
    <joint name="LeftLowerKnee_MimicPitch">
      <hardwareInterface>hardware_interface/EffortJointInterface</hardwareInterface>
    </joint>
    <actuator name="LeftLowerKnee_MimicPitch_actr">
      <hardwareInterface>hardware_interface/EffortJointInterface</hardwareInterface>
      <mechanicalReduction>1</mechanicalReduction>
    </actuator>
  </transmission>
  <transmission name="RightLowerKnee_MimicPitch_tran">
    <type>transmission_interface/SimpleTransmission</type>
    <joint name="RightLowerKnee_MimicPitch">
      <hardwareInterface>hardware_interface/EffortJointInterface</hardwareInterface>
    </joint>
    <actuator name="RightLowerKnee_MimicPitch_actr">
      <hardwareInterface>hardware_interface/EffortJointInterface</hardwareInterface>
      <mechanicalReduction>1</mechanicalReduction>
    </actuator>
  </transmission>
  <transmission name="LeftAnkle_MimicPitch_tran">
    <type>transmission_interface/SimpleTransmission</type>
    <joint name="LeftAnkle_MimicPitch">
      <hardwareInterface>hardware_interface/EffortJointInterface</hardwareInterface>
    </joint>
    <actuator name="LeftAnkle_MimicPitch_actr">
      <hardwareInterface>hardware_interface/EffortJointInterface</hardwareInterface>
      <mechanicalReduction>1</mechanicalReduction>
    </actuator>
  </transmission>
  <transmission name="RightAnkle_MimicPitch_tran">
    <type>transmission_interface/SimpleTransmission</type>
    <joint name="RightAnkle_MimicPitch">
      <hardwareInterface>hardware_interface/EffortJointInterface</hardwareInterface>
    </joint>
    <actuator name="RightAnkle_MimicPitch_actr">
      <hardwareInterface>hardware_interface/EffortJointInterface</hardwareInterface>
      <mechanicalReduction>1</mechanicalReduction>
    </actuator>
  </transmission>
  <transmission name="LeftAnkle_Pitch_tran">
    <type>transmission_interface/SimpleTransmission</type>
    <joint name="LeftAnkle_Pitch">
      <hardwareInterface>hardware_interface/EffortJointInterface</hardwareInterface>
    </joint>
    <actuator name="LeftAnkle_Pitch_actr">
      <hardwareInterface>hardware_interface/EffortJointInterface</hardwareInterface>
      <mechanicalReduction>1</mechanicalReduction>
    </actuator>
  </transmission>
  <transmission name="RightAnkle_Pitch_tran">
    <type>transmission_interface/SimpleTransmission</type>
    <joint name="RightAnkle_Pitch">
      <hardwareInterface>hardware_interface/EffortJointInterface</hardwareInterface>
    </joint>
    <actuator name="RightAnkle_Pitch_actr">
      <hardwareInterface>hardware_interface/EffortJointInterface</hardwareInterface>
      <mechanicalReduction>1</mechanicalReduction>
    </actuator>
  </transmission>
  <transmission name="LeftAnkle_Roll_tran">
    <type>transmission_interface/SimpleTransmission</type>
    <joint name="LeftAnkle_Roll">
      <hardwareInterface>hardware_interface/EffortJointInterface</hardwareInterface>
    </joint>
    <actuator name="LeftAnkle_Roll_actr">
      <hardwareInterface>hardware_interface/EffortJointInterface</hardwareInterface>
      <mechanicalReduction>1</mechanicalReduction>
    </actuator>
  </transmission>
  <transmission name="RightAnkle_Roll_tran">
    <type>transmission_interface/SimpleTransmission</type>
    <joint name="RightAnkle_Roll">
      <hardwareInterface>hardware_interface/EffortJointInterface</hardwareInterface>
    </joint>
    <actuator name="RightAnkle_Roll_actr">
      <hardwareInterface>hardware_interface/EffortJointInterface</hardwareInterface>
      <mechanicalReduction>1</mechanicalReduction>
    </actuator>
  </transmission>
  <gazebo>
    <plugin name="control" filename="libgazebo_ros_control.so"/>
  </gazebo>
  <gazebo reference="base_link">
    <material>Gazebo/Silver</material>
    <mu1>0.2</mu1>
    <mu2>0.2</mu2>
    <selfCollide>true</selfCollide>
    <gravity>true</gravity>
  </gazebo>
  <gazebo reference="HeadUnit_1">
    <material>Gazebo/Silver</material>
    <mu1>0.2</mu1>
    <mu2>0.2</mu2>
    <selfCollide>true</selfCollide>
  </gazebo>
  <gazebo reference="LeftShoulderUnit_1">
    <material>Gazebo/Silver</material>
    <mu1>0.2</mu1>
    <mu2>0.2</mu2>
    <selfCollide>true</selfCollide>
  </gazebo>
  <gazebo reference="RightShoulderUnit_1">
    <material>Gazebo/Silver</material>
    <mu1>0.2</mu1>
    <mu2>0.2</mu2>
    <selfCollide>true</selfCollide>
  </gazebo>
  <gazebo reference="LeftUpperArmUnit_1">
    <material>Gazebo/Silver</material>
    <mu1>0.2</mu1>
    <mu2>0.2</mu2>
    <selfCollide>true</selfCollide>
  </gazebo>
  <gazebo reference="LeftLowerArmUnit_1">
    <material>Gazebo/Silver</material>
    <mu1>0.2</mu1>
    <mu2>0.2</mu2>
    <selfCollide>true</selfCollide>
  </gazebo>
  <gazebo reference="RightUpperArmUnit_1">
    <material>Gazebo/Silver</material>
    <mu1>0.2</mu1>
    <mu2>0.2</mu2>
    <selfCollide>true</selfCollide>
  </gazebo>
  <gazebo reference="RightLowerArmUnit_1">
    <material>Gazebo/Silver</material>
    <mu1>0.2</mu1>
    <mu2>0.2</mu2>
    <selfCollide>true</selfCollide>
  </gazebo>
  <gazebo reference="HipUnit_1">
    <material>Gazebo/Silver</material>
    <mu1>0.2</mu1>
    <mu2>0.2</mu2>
    <selfCollide>true</selfCollide>
  </gazebo>
  <gazebo reference="HipUnit_2">
    <material>Gazebo/Silver</material>
    <mu1>0.2</mu1>
    <mu2>0.2</mu2>
    <selfCollide>true</selfCollide>
  </gazebo>
  <gazebo reference="LegBaseUnit_MIR_1">
    <material>Gazebo/Silver</material>
    <mu1>0.2</mu1>
    <mu2>0.2</mu2>
    <selfCollide>true</selfCollide>
  </gazebo>
  <gazebo reference="LegBaseUnit_1">
    <material>Gazebo/Silver</material>
    <mu1>0.2</mu1>
    <mu2>0.2</mu2>
    <selfCollide>true</selfCollide>
  </gazebo>
  <gazebo reference="ParallelLinksDriveUnit_1">
    <material>Gazebo/Silver</material>
    <mu1>0.2</mu1>
    <mu2>0.2</mu2>
    <selfCollide>true</selfCollide>
  </gazebo>
  <gazebo reference="ParallelLinksDriveUnit_2">
    <material>Gazebo/Silver</material>
    <mu1>0.2</mu1>
    <mu2>0.2</mu2>
    <selfCollide>true</selfCollide>
  </gazebo>
  <gazebo reference="LegBackLinkUnit_1">
    <material>Gazebo/Silver</material>
    <mu1>0.2</mu1>
    <mu2>0.2</mu2>
    <selfCollide>true</selfCollide>
  </gazebo>
  <gazebo reference="LegBackLinkUnit_2">
    <material>Gazebo/Silver</material>
    <mu1>0.2</mu1>
    <mu2>0.2</mu2>
    <selfCollide>true</selfCollide>
  </gazebo>
  <gazebo reference="LeftKneeUnit_1">
    <material>Gazebo/Silver</material>
    <mu1>0.2</mu1>
    <mu2>0.2</mu2>
    <selfCollide>true</selfCollide>
  </gazebo>
  <gazebo reference="RightKneeUnit_1">
    <material>Gazebo/Silver</material>
    <mu1>0.2</mu1>
    <mu2>0.2</mu2>
    <selfCollide>true</selfCollide>
  </gazebo>
  <gazebo reference="LegFrontLinkUnit_1">
    <material>Gazebo/Silver</material>
    <mu1>0.2</mu1>
    <mu2>0.2</mu2>
    <selfCollide>true</selfCollide>
  </gazebo>
  <gazebo reference="LegFrontLinkUnit_2">
    <material>Gazebo/Silver</material>
    <mu1>0.2</mu1>
    <mu2>0.2</mu2>
    <selfCollide>true</selfCollide>
  </gazebo>
  <gazebo reference="LegBackLowerLinkUnit_1">
    <material>Gazebo/Silver</material>
    <mu1>0.2</mu1>
    <mu2>0.2</mu2>
    <selfCollide>true</selfCollide>
  </gazebo>
  <gazebo reference="LegBackLowerLinkUnit_2">
    <material>Gazebo/Silver</material>
    <mu1>0.2</mu1>
    <mu2>0.2</mu2>
    <selfCollide>true</selfCollide>
  </gazebo>
  <gazebo reference="LegFrontLowerLinkUnit_1">
    <material>Gazebo/Silver</material>
    <mu1>0.2</mu1>
    <mu2>0.2</mu2>
    <selfCollide>true</selfCollide>
  </gazebo>
  <gazebo reference="LegFrontLowerLinkUnit_2">
    <material>Gazebo/Silver</material>
    <mu1>0.2</mu1>
    <mu2>0.2</mu2>
    <selfCollide>true</selfCollide>
  </gazebo>
  <gazebo reference="ParallelLinksDriveUnit_3">
    <material>Gazebo/Silver</material>
    <mu1>0.2</mu1>
    <mu2>0.2</mu2>
    <selfCollide>true</selfCollide>
  </gazebo>
  <gazebo reference="ParallelLinksDriveUnit_4">
    <material>Gazebo/Silver</material>
    <mu1>0.2</mu1>
    <mu2>0.2</mu2>
    <selfCollide>true</selfCollide>
  </gazebo>
  <gazebo reference="LegBaseUnit_2">
    <material>Gazebo/Silver</material>
    <mu1>0.2</mu1>
    <mu2>0.2</mu2>
    <selfCollide>true</selfCollide>
  </gazebo>
  <gazebo reference="LegBaseUnit_MIR_2">
    <material>Gazebo/Silver</material>
    <mu1>0.2</mu1>
    <mu2>0.2</mu2>
    <selfCollide>true</selfCollide>
  </gazebo>
  <gazebo reference="LeftFootUnit_1">
    <material>Gazebo/Silver</material>
    <mu1>0.2</mu1>
    <mu2>0.2</mu2>
    <selfCollide>true</selfCollide>
  </gazebo>
  <gazebo reference="RightFootUnit_1">
    <material>Gazebo/Silver</material>
    <mu1>0.2</mu1>
    <mu2>0.2</mu2>
    <selfCollide>true</selfCollide>
  </gazebo>
  <link name="base_link">
    <inertial>
      <origin xyz="-0.0010467131908389858 -3.255353520866945e-15 0.5326767494571166" rpy="0 0 0"/>
      <mass value="0.9271157570401507"/>
      <inertia ixx="0.009724" iyy="0.00746" izz="0.006739" ixy="0.0" iyz="0.0" ixz="0.000124"/>
    </inertial>
    <visual>
      <origin xyz="0 0 0" rpy="0 0 0"/>
      <geometry>
        <mesh filename="package://SUSTAINA-OP2_description/meshes/base_link.stl" scale="0.001 0.001 0.001"/>
      </geometry>
      <material name="silver"/>
    </visual>
    <collision>
      <origin xyz="0 0 0" rpy="0 0 0"/>
      <geometry>
        <mesh filename="package://SUSTAINA-OP2_description/meshes/base_link.stl" scale="0.001 0.001 0.001"/>
      </geometry>
    </collision>
  </link>
  <link name="HeadUnit_1">
    <inertial>
      <origin xyz="0.025261689808736987 -1.1909789022036562e-16 0.2894059271198942" rpy="0 0 0"/>
      <mass value="0.5591935074952623"/>
      <inertia ixx="0.000665" iyy="0.000737" izz="0.000626" ixy="0.0" iyz="-0.0" ixz="-0.000111"/>
    </inertial>
    <visual>
      <origin xyz="-0.0 0.0 -0.4155" rpy="0 0 0"/>
      <geometry>
        <mesh filename="package://SUSTAINA-OP2_description/meshes/HeadUnit_1.stl" scale="0.001 0.001 0.001"/>
      </geometry>
      <material name="silver"/>
    </visual>
    <collision>
      <origin xyz="-0.0 0.0 -0.4155" rpy="0 0 0"/>
      <geometry>
        <mesh filename="package://SUSTAINA-OP2_description/meshes/HeadUnit_1.stl" scale="0.001 0.001 0.001"/>
      </geometry>
    </collision>
  </link>
  <link name="LeftShoulderUnit_1">
    <inertial>
      <origin xyz="-2.3458577336119604e-05 0.13973776870239699 0.17351251832141845" rpy="0 0 0"/>
      <mass value="0.1381405613291457"/>
      <inertia ixx="9.3e-05" iyy="0.000152" izz="0.000144" ixy="-0.0" iyz="-1e-06" ixz="1e-06"/>
    </inertial>
    <visual>
      <origin xyz="-0.0 0.0 -0.4155" rpy="0 0 0"/>
      <geometry>
        <mesh filename="package://SUSTAINA-OP2_description/meshes/LeftShoulderUnit_1.stl" scale="0.001 0.001 0.001"/>
      </geometry>
      <material name="silver"/>
    </visual>
    <collision>
      <origin xyz="-0.0 0.0 -0.4155" rpy="0 0 0"/>
      <geometry>
        <mesh filename="package://SUSTAINA-OP2_description/meshes/LeftShoulderUnit_1.stl" scale="0.001 0.001 0.001"/>
      </geometry>
    </collision>
  </link>
  <link name="RightShoulderUnit_1">
    <inertial>
      <origin xyz="-2.345857736192408e-05 -0.13973776870252874 0.17351251832115333" rpy="0 0 0"/>
      <mass value="0.13814056132999106"/>
      <inertia ixx="9.3e-05" iyy="0.000152" izz="0.000144" ixy="0.0" iyz="1e-06" ixz="1e-06"/>
    </inertial>
    <visual>
      <origin xyz="-0.0 0.0 -0.4155" rpy="0 0 0"/>
      <geometry>
        <mesh filename="package://SUSTAINA-OP2_description/meshes/RightShoulderUnit_1.stl" scale="0.001 0.001 0.001"/>
      </geometry>
      <material name="silver"/>
    </visual>
    <collision>
      <origin xyz="-0.0 0.0 -0.4155" rpy="0 0 0"/>
      <geometry>
        <mesh filename="package://SUSTAINA-OP2_description/meshes/RightShoulderUnit_1.stl" scale="0.001 0.001 0.001"/>
      </geometry>
    </collision>
  </link>
  <link name="LeftUpperArmUnit_1">
    <inertial>
      <origin xyz="0.0064660185580925275 0.03179261057432116 -0.1299243669969678" rpy="0 0 0"/>
      <mass value="0.09863675532745937"/>
      <inertia ixx="0.000147" iyy="0.000165" izz="4.6e-05" ixy="-0.0" iyz="2e-06" ixz="5e-06"/>
    </inertial>
    <visual>
      <origin xyz="-0.0 -0.1075 -0.5995" rpy="0 0 0"/>
      <geometry>
        <mesh filename="package://SUSTAINA-OP2_description/meshes/LeftUpperArmUnit_1.stl" scale="0.001 0.001 0.001"/>
      </geometry>
      <material name="silver"/>
    </visual>
    <collision>
      <origin xyz="-0.0 -0.1075 -0.5995" rpy="0 0 0"/>
      <geometry>
        <mesh filename="package://SUSTAINA-OP2_description/meshes/LeftUpperArmUnit_1.stl" scale="0.001 0.001 0.001"/>
      </geometry>
    </collision>
  </link>
  <link name="LeftLowerArmUnit_1">
    <inertial>
      <origin xyz="-0.00018776400404989002 -0.00033522748588690754 -0.21295824658334395" rpy="0 0 0"/>
      <mass value="0.07301293817819124"/>
      <inertia ixx="0.000244" iyy="0.000221" izz="7.5e-05" ixy="-0.0" iyz="2e-06" ixz="1e-06"/>
    </inertial>
    <visual>
      <origin xyz="-0.0 -0.1375 -0.5745" rpy="0 0 0"/>
      <geometry>
        <mesh filename="package://SUSTAINA-OP2_description/meshes/LeftLowerArmUnit_1.stl" scale="0.001 0.001 0.001"/>
      </geometry>
      <material name="silver"/>
    </visual>
    <collision>
      <origin xyz="-0.0 -0.1375 -0.5745" rpy="0 0 0"/>
      <geometry>
        <mesh filename="package://SUSTAINA-OP2_description/meshes/LeftLowerArmUnit_1.stl" scale="0.001 0.001 0.001"/>
      </geometry>
    </collision>
  </link>
  <link name="RightUpperArmUnit_1">
    <inertial>
      <origin xyz="0.006466018557314967 -0.03179261057443668 -0.1299243669997439" rpy="0 0 0"/>
      <mass value="0.09863675533367823"/>
      <inertia ixx="0.000147" iyy="0.000165" izz="4.6e-05" ixy="0.0" iyz="-2e-06" ixz="5e-06"/>
    </inertial>
    <visual>
      <origin xyz="-0.0 0.1075 -0.5995" rpy="0 0 0"/>
      <geometry>
        <mesh filename="package://SUSTAINA-OP2_description/meshes/RightUpperArmUnit_1.stl" scale="0.001 0.001 0.001"/>
      </geometry>
      <material name="silver"/>
    </visual>
    <collision>
      <origin xyz="-0.0 0.1075 -0.5995" rpy="0 0 0"/>
      <geometry>
        <mesh filename="package://SUSTAINA-OP2_description/meshes/RightUpperArmUnit_1.stl" scale="0.001 0.001 0.001"/>
      </geometry>
    </collision>
  </link>
  <link name="RightLowerArmUnit_1">
    <inertial>
      <origin xyz="-0.00018776400404976471 0.0003352274858862414 -0.21295824658334767" rpy="0 0 0"/>
      <mass value="0.07301293817819124"/>
      <inertia ixx="0.000244" iyy="0.000221" izz="7.5e-05" ixy="0.0" iyz="-2e-06" ixz="1e-06"/>
    </inertial>
    <visual>
      <origin xyz="-0.0 0.1375 -0.5745" rpy="0 0 0"/>
      <geometry>
        <mesh filename="package://SUSTAINA-OP2_description/meshes/RightLowerArmUnit_1.stl" scale="0.001 0.001 0.001"/>
      </geometry>
      <material name="silver"/>
    </visual>
    <collision>
      <origin xyz="-0.0 0.1375 -0.5745" rpy="0 0 0"/>
      <geometry>
        <mesh filename="package://SUSTAINA-OP2_description/meshes/RightLowerArmUnit_1.stl" scale="0.001 0.001 0.001"/>
      </geometry>
    </collision>
  </link>
  <link name="HipUnit_1">
    <inertial>
      <origin xyz="-0.011281998373960616 0.05499999999999997 -0.010965679840041598" rpy="0 0 0"/>
      <mass value="0.019191836372432405"/>
      <inertia ixx="5e-06" iyy="1.5e-05" izz="1.3e-05" ixy="0.0" iyz="0.0" ixz="-0.0"/>
    </inertial>
    <visual>
      <origin xyz="-0.0 0.0 -0.4155" rpy="0 0 0"/>
      <geometry>
        <mesh filename="package://SUSTAINA-OP2_description/meshes/HipUnit_1.stl" scale="0.001 0.001 0.001"/>
      </geometry>
      <material name="silver"/>
    </visual>
    <collision>
      <origin xyz="-0.0 0.0 -0.4155" rpy="0 0 0"/>
      <geometry>
        <mesh filename="package://SUSTAINA-OP2_description/meshes/HipUnit_1.stl" scale="0.001 0.001 0.001"/>
      </geometry>
    </collision>
  </link>
  <link name="HipUnit_2">
    <inertial>
      <origin xyz="-0.011281998373960734 -0.05499999999999992 -0.010965679840041376" rpy="0 0 0"/>
      <mass value="0.019191836372432405"/>
      <inertia ixx="5e-06" iyy="1.5e-05" izz="1.3e-05" ixy="0.0" iyz="0.0" ixz="-0.0"/>
    </inertial>
    <visual>
      <origin xyz="-0.0 0.0 -0.4155" rpy="0 0 0"/>
      <geometry>
        <mesh filename="package://SUSTAINA-OP2_description/meshes/HipUnit_2.stl" scale="0.001 0.001 0.001"/>
      </geometry>
      <material name="silver"/>
    </visual>
    <collision>
      <origin xyz="-0.0 0.0 -0.4155" rpy="0 0 0"/>
      <geometry>
        <mesh filename="package://SUSTAINA-OP2_description/meshes/HipUnit_2.stl" scale="0.001 0.001 0.001"/>
      </geometry>
    </collision>
  </link>
  <link name="LegBaseUnit_MIR_1">
    <inertial>
      <origin xyz="-0.040301077484469046 0.00019854969603057965 -0.04390273346183976" rpy="0 0 0"/>
      <mass value="0.15736896457126398"/>
      <inertia ixx="5.7e-05" iyy="0.00019" izz="0.000174" ixy="-1e-06" iyz="-1e-06" ixz="7e-06"/>
    </inertial>
    <visual>
      <origin xyz="-0.0 -0.055 -0.4155" rpy="0 0 0"/>
      <geometry>
        <mesh filename="package://SUSTAINA-OP2_description/meshes/LegBaseUnit_MIR_1.stl" scale="0.001 0.001 0.001"/>
      </geometry>
      <material name="silver"/>
    </visual>
    <collision>
      <origin xyz="-0.0 -0.055 -0.4155" rpy="0 0 0"/>
      <geometry>
        <mesh filename="package://SUSTAINA-OP2_description/meshes/LegBaseUnit_MIR_1.stl" scale="0.001 0.001 0.001"/>
      </geometry>
    </collision>
  </link>
  <link name="LegBaseUnit_1">
    <inertial>
      <origin xyz="-0.04030107748963799 -0.11019854691805855 -0.043902733461839594" rpy="0 0 0"/>
      <mass value="0.1573689645712646"/>
      <inertia ixx="5.7e-05" iyy="0.00019" izz="0.000174" ixy="1e-06" iyz="1e-06" ixz="7e-06"/>
    </inertial>
    <visual>
      <origin xyz="-0.0 -0.055 -0.4155" rpy="0 0 0"/>
      <geometry>
        <mesh filename="package://SUSTAINA-OP2_description/meshes/LegBaseUnit_1.stl" scale="0.001 0.001 0.001"/>
      </geometry>
      <material name="silver"/>
    </visual>
    <collision>
      <origin xyz="-0.0 -0.055 -0.4155" rpy="0 0 0"/>
      <geometry>
        <mesh filename="package://SUSTAINA-OP2_description/meshes/LegBaseUnit_1.stl" scale="0.001 0.001 0.001"/>
      </geometry>
    </collision>
  </link>
  <link name="ParallelLinksDriveUnit_1">
    <inertial>
      <origin xyz="-0.022766434387027887 -2.42861286636753e-16 -0.0051420012022839745" rpy="0 0 0"/>
      <mass value="0.011867201966586308"/>
      <inertia ixx="1e-05" iyy="3e-06" izz="1.2e-05" ixy="-0.0" iyz="-0.0" ixz="-0.0"/>
    </inertial>
    <visual>
      <origin xyz="-0.0 -0.055 -0.3745" rpy="0 0 0"/>
      <geometry>
        <mesh filename="package://SUSTAINA-OP2_description/meshes/ParallelLinksDriveUnit_1.stl" scale="0.001 0.001 0.001"/>
      </geometry>
      <material name="silver"/>
    </visual>
    <collision>
      <origin xyz="-0.0 -0.055 -0.3745" rpy="0 0 0"/>
      <geometry>
        <mesh filename="package://SUSTAINA-OP2_description/meshes/ParallelLinksDriveUnit_1.stl" scale="0.001 0.001 0.001"/>
      </geometry>
    </collision>
  </link>
  <link name="ParallelLinksDriveUnit_2">
    <inertial>
      <origin xyz="-0.022766434387028002 -1.5959455978986625e-16 -0.0051420012022837525" rpy="0 0 0"/>
      <mass value="0.011867201966586308"/>
      <inertia ixx="1e-05" iyy="3e-06" izz="1.2e-05" ixy="-0.0" iyz="-0.0" ixz="-0.0"/>
    </inertial>
    <visual>
      <origin xyz="-0.0 0.055 -0.3745" rpy="0 0 0"/>
      <geometry>
        <mesh filename="package://SUSTAINA-OP2_description/meshes/ParallelLinksDriveUnit_2.stl" scale="0.001 0.001 0.001"/>
      </geometry>
      <material name="silver"/>
    </visual>
    <collision>
      <origin xyz="-0.0 0.055 -0.3745" rpy="0 0 0"/>
      <geometry>
        <mesh filename="package://SUSTAINA-OP2_description/meshes/ParallelLinksDriveUnit_2.stl" scale="0.001 0.001 0.001"/>
      </geometry>
    </collision>
  </link>
  <link name="LegBackLinkUnit_1">
    <inertial>
      <origin xyz="-0.03369971644247034 -5.551115123125783e-17 -0.08485830204635608" rpy="0 0 0"/>
      <mass value="0.030239245930894793"/>
      <inertia ixx="5.5e-05" iyy="3.1e-05" izz="2.6e-05" ixy="-0.0" iyz="0.0" ixz="1e-06"/>
    </inertial>
    <visual>
      <origin xyz="-0.0 -0.055 -0.3745" rpy="0 0 0"/>
      <geometry>
        <mesh filename="package://SUSTAINA-OP2_description/meshes/LegBackLinkUnit_1.stl" scale="0.001 0.001 0.001"/>
      </geometry>
      <material name="silver"/>
    </visual>
    <collision>
      <origin xyz="-0.0 -0.055 -0.3745" rpy="0 0 0"/>
      <geometry>
        <mesh filename="package://SUSTAINA-OP2_description/meshes/LegBackLinkUnit_1.stl" scale="0.001 0.001 0.001"/>
      </geometry>
    </collision>
  </link>
  <link name="LegBackLinkUnit_2">
    <inertial>
      <origin xyz="-0.033699716442470475 -0.10999999999999999 -0.08485830204635586" rpy="0 0 0"/>
      <mass value="0.030239245930894793"/>
      <inertia ixx="5.5e-05" iyy="3.1e-05" izz="2.6e-05" ixy="-0.0" iyz="0.0" ixz="1e-06"/>
    </inertial>
    <visual>
      <origin xyz="-0.0 -0.055 -0.3745" rpy="0 0 0"/>
      <geometry>
        <mesh filename="package://SUSTAINA-OP2_description/meshes/LegBackLinkUnit_2.stl" scale="0.001 0.001 0.001"/>
      </geometry>
      <material name="silver"/>
    </visual>
    <collision>
      <origin xyz="-0.0 -0.055 -0.3745" rpy="0 0 0"/>
      <geometry>
        <mesh filename="package://SUSTAINA-OP2_description/meshes/LegBackLinkUnit_2.stl" scale="0.001 0.001 0.001"/>
      </geometry>
    </collision>
  </link>
  <link name="LeftKneeUnit_1">
    <inertial>
      <origin xyz="0.008979321344978072 0.0003900640155121149 -0.1450000000000115" rpy="0 0 0"/>
      <mass value="0.17269011716727442"/>
      <inertia ixx="0.000184" iyy="0.000196" izz="9.5e-05" ixy="-2e-06" iyz="0.0" ixz="-0.0"/>
    </inertial>
    <visual>
      <origin xyz="0.032 -0.055 -0.3595" rpy="0 0 0"/>
      <geometry>
        <mesh filename="package://SUSTAINA-OP2_description/meshes/LeftKneeUnit_1.stl" scale="0.001 0.001 0.001"/>
      </geometry>
      <material name="silver"/>
    </visual>
    <collision>
      <origin xyz="0.032 -0.055 -0.3595" rpy="0 0 0"/>
      <geometry>
        <mesh filename="package://SUSTAINA-OP2_description/meshes/LeftKneeUnit_1.stl" scale="0.001 0.001 0.001"/>
      </geometry>
    </collision>
  </link>
  <link name="RightKneeUnit_1">
    <inertial>
      <origin xyz="0.008979321344977944 -0.11039006401551212 -0.1450000000000114" rpy="0 0 0"/>
      <mass value="0.17269011716727442"/>
      <inertia ixx="0.000184" iyy="0.000196" izz="9.5e-05" ixy="2e-06" iyz="-0.0" ixz="-0.0"/>
    </inertial>
    <visual>
      <origin xyz="0.032 -0.055 -0.3595" rpy="0 0 0"/>
      <geometry>
        <mesh filename="package://SUSTAINA-OP2_description/meshes/RightKneeUnit_1.stl" scale="0.001 0.001 0.001"/>
      </geometry>
      <material name="silver"/>
    </visual>
    <collision>
      <origin xyz="0.032 -0.055 -0.3595" rpy="0 0 0"/>
      <geometry>
        <mesh filename="package://SUSTAINA-OP2_description/meshes/RightKneeUnit_1.stl" scale="0.001 0.001 0.001"/>
      </geometry>
    </collision>
  </link>
  <link name="LegFrontLinkUnit_1">
    <inertial>
      <origin xyz="0.03919185411016325 -1.249000902703301e-16 0.08479720460592663" rpy="0 0 0"/>
      <mass value="0.028919679137475493"/>
      <inertia ixx="5.2e-05" iyy="2.9e-05" izz="2.5e-05" ixy="-0.0" iyz="-0.0" ixz="-0.0"/>
    </inertial>
    <visual>
      <origin xyz="0.032 -0.055 -0.227" rpy="0 0 0"/>
      <geometry>
        <mesh filename="package://SUSTAINA-OP2_description/meshes/LegFrontLinkUnit_1.stl" scale="0.001 0.001 0.001"/>
      </geometry>
      <material name="silver"/>
    </visual>
    <collision>
      <origin xyz="0.032 -0.055 -0.227" rpy="0 0 0"/>
      <geometry>
        <mesh filename="package://SUSTAINA-OP2_description/meshes/LegFrontLinkUnit_1.stl" scale="0.001 0.001 0.001"/>
      </geometry>
    </collision>
  </link>
  <link name="LegFrontLinkUnit_2">
    <inertial>
      <origin xyz="0.03919185411016313 -6.938893903907228e-18 0.08479720460592674" rpy="0 0 0"/>
      <mass value="0.028919679137475493"/>
      <inertia ixx="5.2e-05" iyy="2.9e-05" izz="2.5e-05" ixy="-0.0" iyz="0.0" ixz="-0.0"/>
    </inertial>
    <visual>
      <origin xyz="0.032 0.055 -0.227" rpy="0 0 0"/>
      <geometry>
        <mesh filename="package://SUSTAINA-OP2_description/meshes/LegFrontLinkUnit_2.stl" scale="0.001 0.001 0.001"/>
      </geometry>
      <material name="silver"/>
    </visual>
    <collision>
      <origin xyz="0.032 0.055 -0.227" rpy="0 0 0"/>
      <geometry>
        <mesh filename="package://SUSTAINA-OP2_description/meshes/LegFrontLinkUnit_2.stl" scale="0.001 0.001 0.001"/>
      </geometry>
    </collision>
  </link>
  <link name="LegBackLowerLinkUnit_1">
    <inertial>
      <origin xyz="-0.0016997164424703143 -9.71445146547012e-17 -0.08764169795364102" rpy="0 0 0"/>
      <mass value="0.030239245930894793"/>
      <inertia ixx="5.5e-05" iyy="3.1e-05" izz="2.6e-05" ixy="-0.0" iyz="0.0" ixz="-1e-06"/>
    </inertial>
    <visual>
      <origin xyz="0.032 -0.055 -0.227" rpy="0 0 0"/>
      <geometry>
        <mesh filename="package://SUSTAINA-OP2_description/meshes/LegBackLowerLinkUnit_1.stl" scale="0.001 0.001 0.001"/>
      </geometry>
      <material name="silver"/>
    </visual>
    <collision>
      <origin xyz="0.032 -0.055 -0.227" rpy="0 0 0"/>
      <geometry>
        <mesh filename="package://SUSTAINA-OP2_description/meshes/LegBackLowerLinkUnit_1.stl" scale="0.001 0.001 0.001"/>
      </geometry>
    </collision>
  </link>
  <link name="LegBackLowerLinkUnit_2">
    <inertial>
      <origin xyz="-0.0016997164424704253 0.0 -0.08764169795364096" rpy="0 0 0"/>
      <mass value="0.030239245930894793"/>
      <inertia ixx="5.5e-05" iyy="3.1e-05" izz="2.6e-05" ixy="0.0" iyz="0.0" ixz="-1e-06"/>
    </inertial>
    <visual>
      <origin xyz="0.032 0.055 -0.227" rpy="0 0 0"/>
      <geometry>
        <mesh filename="package://SUSTAINA-OP2_description/meshes/LegBackLowerLinkUnit_2.stl" scale="0.001 0.001 0.001"/>
      </geometry>
      <material name="silver"/>
    </visual>
    <collision>
      <origin xyz="0.032 0.055 -0.227" rpy="0 0 0"/>
      <geometry>
        <mesh filename="package://SUSTAINA-OP2_description/meshes/LegBackLowerLinkUnit_2.stl" scale="0.001 0.001 0.001"/>
      </geometry>
    </collision>
  </link>
  <link name="LegFrontLowerLinkUnit_1">
    <inertial>
      <origin xyz="0.0391918541101633 -1.3183898417423734e-16 -0.10979720460592371" rpy="0 0 0"/>
      <mass value="0.02891967913747547"/>
      <inertia ixx="5.2e-05" iyy="2.9e-05" izz="2.5e-05" ixy="-0.0" iyz="0.0" ixz="0.0"/>
    </inertial>
    <visual>
      <origin xyz="0.032 -0.055 -0.227" rpy="0 0 0"/>
      <geometry>
        <mesh filename="package://SUSTAINA-OP2_description/meshes/LegFrontLowerLinkUnit_1.stl" scale="0.001 0.001 0.001"/>
      </geometry>
      <material name="silver"/>
    </visual>
    <collision>
      <origin xyz="0.032 -0.055 -0.227" rpy="0 0 0"/>
      <geometry>
        <mesh filename="package://SUSTAINA-OP2_description/meshes/LegFrontLowerLinkUnit_1.stl" scale="0.001 0.001 0.001"/>
      </geometry>
    </collision>
  </link>
  <link name="LegFrontLowerLinkUnit_2">
    <inertial>
      <origin xyz="0.039191854110163155 2.0816681711721685e-17 -0.10979720460592363" rpy="0 0 0"/>
      <mass value="0.02891967913747547"/>
      <inertia ixx="5.2e-05" iyy="2.9e-05" izz="2.5e-05" ixy="-0.0" iyz="0.0" ixz="0.0"/>
    </inertial>
    <visual>
      <origin xyz="0.032 0.055 -0.227" rpy="0 0 0"/>
      <geometry>
        <mesh filename="package://SUSTAINA-OP2_description/meshes/LegFrontLowerLinkUnit_2.stl" scale="0.001 0.001 0.001"/>
      </geometry>
      <material name="silver"/>
    </visual>
    <collision>
      <origin xyz="0.032 0.055 -0.227" rpy="0 0 0"/>
      <geometry>
        <mesh filename="package://SUSTAINA-OP2_description/meshes/LegFrontLowerLinkUnit_2.stl" scale="0.001 0.001 0.001"/>
      </geometry>
    </collision>
  </link>
  <link name="ParallelLinksDriveUnit_3">
    <inertial>
      <origin xyz="0.009233565612972134 4.163336342344337e-17 -0.009857998797713027" rpy="0 0 0"/>
      <mass value="0.011867201966586308"/>
      <inertia ixx="1e-05" iyy="3e-06" izz="1.2e-05" ixy="0.0" iyz="0.0" ixz="0.0"/>
    </inertial>
    <visual>
      <origin xyz="0.032 -0.055 -0.0695" rpy="0 0 0"/>
      <geometry>
        <mesh filename="package://SUSTAINA-OP2_description/meshes/ParallelLinksDriveUnit_3.stl" scale="0.001 0.001 0.001"/>
      </geometry>
      <material name="silver"/>
    </visual>
    <collision>
      <origin xyz="0.032 -0.055 -0.0695" rpy="0 0 0"/>
      <geometry>
        <mesh filename="package://SUSTAINA-OP2_description/meshes/ParallelLinksDriveUnit_3.stl" scale="0.001 0.001 0.001"/>
      </geometry>
    </collision>
  </link>
  <link name="ParallelLinksDriveUnit_4">
    <inertial>
      <origin xyz="0.009233565612972103 -0.1099999999999999 -0.009857998797713013" rpy="0 0 0"/>
      <mass value="0.011867201966586308"/>
      <inertia ixx="1e-05" iyy="3e-06" izz="1.2e-05" ixy="0.0" iyz="-0.0" ixz="0.0"/>
    </inertial>
    <visual>
      <origin xyz="0.032 -0.055 -0.0695" rpy="0 0 0"/>
      <geometry>
        <mesh filename="package://SUSTAINA-OP2_description/meshes/ParallelLinksDriveUnit_4.stl" scale="0.001 0.001 0.001"/>
      </geometry>
      <material name="silver"/>
    </visual>
    <collision>
      <origin xyz="0.032 -0.055 -0.0695" rpy="0 0 0"/>
      <geometry>
        <mesh filename="package://SUSTAINA-OP2_description/meshes/ParallelLinksDriveUnit_4.stl" scale="0.001 0.001 0.001"/>
      </geometry>
    </collision>
  </link>
  <link name="LegBaseUnit_2">
    <inertial>
      <origin xyz="-0.04030107748963787 -0.054801453081941516 -0.37159726653815717" rpy="0 0 0"/>
      <mass value="0.1573689645712646"/>
      <inertia ixx="5.7e-05" iyy="0.00019" izz="0.000174" ixy="-1e-06" iyz="1e-06" ixz="-7e-06"/>
    </inertial>
    <visual>
      <origin xyz="-0.0 -0.11 -0.429" rpy="0 0 0"/>
      <geometry>
        <mesh filename="package://SUSTAINA-OP2_description/meshes/LegBaseUnit_2.stl" scale="0.001 0.001 0.001"/>
      </geometry>
      <material name="silver"/>
    </visual>
    <collision>
      <origin xyz="-0.0 -0.11 -0.429" rpy="0 0 0"/>
      <geometry>
        <mesh filename="package://SUSTAINA-OP2_description/meshes/LegBaseUnit_2.stl" scale="0.001 0.001 0.001"/>
      </geometry>
    </collision>
  </link>
  <link name="LegBaseUnit_MIR_2">
    <inertial>
      <origin xyz="-0.040301077484469004 -0.11019854969603077 -0.3170972665381573" rpy="0 0 0"/>
      <mass value="0.15736896457126398"/>
      <inertia ixx="5.7e-05" iyy="0.00019" izz="0.000174" ixy="1e-06" iyz="-1e-06" ixz="-7e-06"/>
    </inertial>
    <visual>
      <origin xyz="-0.0 -0.055 -0.3745" rpy="0 0 0"/>
      <geometry>
        <mesh filename="package://SUSTAINA-OP2_description/meshes/LegBaseUnit_MIR_2.stl" scale="0.001 0.001 0.001"/>
      </geometry>
      <material name="silver"/>
    </visual>
    <collision>
      <origin xyz="-0.0 -0.055 -0.3745" rpy="0 0 0"/>
      <geometry>
        <mesh filename="package://SUSTAINA-OP2_description/meshes/LegBaseUnit_MIR_2.stl" scale="0.001 0.001 0.001"/>
      </geometry>
    </collision>
  </link>
  <link name="LeftFootUnit_1">
    <inertial>
      <origin xyz="-0.002935469127042626 0.06241018105962813 -0.41529201933131205" rpy="0 0 0"/>
      <mass value="0.08771716056386779"/>
      <inertia ixx="7e-05" iyy="0.000259" izz="0.000317" ixy="-2e-06" iyz="2e-06" ixz="2e-06"/>
    </inertial>
    <visual>
      <origin xyz="-0.0 0.0 -0.429" rpy="0 0 0"/>
      <geometry>
        <mesh filename="package://SUSTAINA-OP2_description/meshes/LeftFootUnit_1.stl" scale="0.001 0.001 0.001"/>
      </geometry>
      <material name="silver"/>
    </visual>
    <collision>
      <origin xyz="-0.0 0.0 -0.429" rpy="0 0 0"/>
      <geometry>
        <mesh filename="package://SUSTAINA-OP2_description/meshes/LeftFootUnit_1.stl" scale="0.001 0.001 0.001"/>
      </geometry>
    </collision>
  </link>
  <link name="RightFootUnit_1">
    <inertial>
      <origin xyz="-0.0029354691270426976 -0.06241018105966262 -0.41529201933131205" rpy="0 0 0"/>
      <mass value="0.08771716056386795"/>
      <inertia ixx="7e-05" iyy="0.000259" izz="0.000317" ixy="2e-06" iyz="-2e-06" ixz="2e-06"/>
    </inertial>
    <visual>
      <origin xyz="-0.0 0.0 -0.429" rpy="0 0 0"/>
      <geometry>
        <mesh filename="package://SUSTAINA-OP2_description/meshes/RightFootUnit_1.stl" scale="0.001 0.001 0.001"/>
      </geometry>
      <material name="silver"/>
    </visual>
    <collision>
      <origin xyz="-0.0 0.0 -0.429" rpy="0 0 0"/>
      <geometry>
        <mesh filename="package://SUSTAINA-OP2_description/meshes/RightFootUnit_1.stl" scale="0.001 0.001 0.001"/>
      </geometry>
    </collision>
  </link>
  <joint name="Head_Yaw" type="revolute">
    <origin xyz="0.0 0.0 0.4155" rpy="0 0 0"/>
    <parent link="base_link"/>
    <child link="HeadUnit_1"/>
    <axis xyz="0.0 -0.0 1.0"/>
    <limit upper="2.356194" lower="-2.356194" effort="100" velocity="100"/>
  </joint>
  <joint name="LeftShoulder_Pitch" type="revolute">
    <origin xyz="0.0 0.0 0.4155" rpy="0 0 0"/>
    <parent link="base_link"/>
    <child link="LeftShoulderUnit_1"/>
    <axis xyz="0.0 1.0 -0.0"/>
    <limit upper="3.141593" lower="-3.141593" effort="100" velocity="100"/>
  </joint>
  <joint name="RightShoulder_Pitch" type="revolute">
    <origin xyz="0.0 0.0 0.4155" rpy="0 0 0"/>
    <parent link="base_link"/>
    <child link="RightShoulderUnit_1"/>
    <axis xyz="0.0 1.0 -0.0"/>
    <limit upper="3.141593" lower="-3.141593" effort="100" velocity="100"/>
  </joint>
  <joint name="LeftShoulder_Roll" type="revolute">
    <origin xyz="0.0 0.1075 0.184" rpy="0 0 0"/>
    <parent link="LeftShoulderUnit_1"/>
    <child link="LeftUpperArmUnit_1"/>
    <axis xyz="1.0 -0.0 0.0"/>
    <limit upper="1.570796" lower="-0.523599" effort="100" velocity="100"/>
  </joint>
  <joint name="LeftElbow_Pitch" type="revolute">
    <origin xyz="0.0 0.03 -0.025" rpy="0 0 0"/>
    <parent link="LeftUpperArmUnit_1"/>
    <child link="LeftLowerArmUnit_1"/>
    <axis xyz="0.0 1.0 -0.0"/>
    <limit upper="0.0" lower="-2.094395" effort="100" velocity="100"/>
  </joint>
  <joint name="RightShoulder_Roll" type="revolute">
    <origin xyz="0.0 -0.1075 0.184" rpy="0 0 0"/>
    <parent link="RightShoulderUnit_1"/>
    <child link="RightUpperArmUnit_1"/>
    <axis xyz="1.0 0.0 0.0"/>
    <limit upper="0.523599" lower="-1.570796" effort="100" velocity="100"/>
  </joint>
  <joint name="RightElbow_Pitch" type="revolute">
    <origin xyz="0.0 -0.03 -0.025" rpy="0 0 0"/>
    <parent link="RightUpperArmUnit_1"/>
    <child link="RightLowerArmUnit_1"/>
    <axis xyz="-0.0 1.0 -0.0"/>
    <limit upper="0.0" lower="-2.094395" effort="100" velocity="100"/>
  </joint>
  <joint name="LeftHip_Yaw" type="revolute">
    <origin xyz="0.0 0.0 0.4155" rpy="0 0 0"/>
    <parent link="base_link"/>
    <child link="HipUnit_1"/>
    <axis xyz="0.0 -0.0 1.0"/>
    <limit upper="0.785398" lower="-0.785398" effort="100" velocity="100"/>
  </joint>
  <joint name="RightHip_Yaw" type="revolute">
    <origin xyz="0.0 0.0 0.4155" rpy="0 0 0"/>
    <parent link="base_link"/>
    <child link="HipUnit_2"/>
    <axis xyz="0.0 -0.0 1.0"/>
    <limit upper="0.785398" lower="-0.785398" effort="100" velocity="100"/>
  </joint>
  <joint name="LeftHip_Roll" type="revolute">
    <origin xyz="0.0 0.055 0.0" rpy="0 0 0"/>
    <parent link="HipUnit_1"/>
    <child link="LegBaseUnit_MIR_1"/>
    <axis xyz="1.0 0.0 0.0"/>
    <limit upper="1.047198" lower="-1.047198" effort="100" velocity="100"/>
  </joint>
  <joint name="RightHip_Roll" type="revolute">
    <origin xyz="0.0 0.055 0.0" rpy="0 0 0"/>
    <parent link="HipUnit_2"/>
    <child link="LegBaseUnit_1"/>
    <axis xyz="1.0 0.0 0.0"/>
    <limit upper="1.047198" lower="-1.047198" effort="100" velocity="100"/>
  </joint>
  <joint name="LeftHip_MimicPitch" type="revolute">
    <origin xyz="0.0 0.0 -0.041" rpy="0 0 0"/>
    <parent link="LegBaseUnit_MIR_1"/>
    <child link="ParallelLinksDriveUnit_1"/>
    <axis xyz="-0.0 -1.0 0.0"/>
    <limit upper="1.570796" lower="-0.523599" effort="100" velocity="100"/>
  </joint>
  <joint name="RightHip_MimicPitch" type="revolute">
    <origin xyz="0.0 -0.11 -0.041" rpy="0 0 0"/>
    <parent link="LegBaseUnit_1"/>
    <child link="ParallelLinksDriveUnit_2"/>
    <axis xyz="0.0 -1.0 0.0"/>
    <limit upper="1.570796" lower="-0.523599" effort="100" velocity="100"/>
  </joint>
  <joint name="LeftHipBackLink" type="continuous">
    <origin xyz="0.0 0.0 0.0" rpy="0 0 0"/>
    <parent link="ParallelLinksDriveUnit_1"/>
    <child link="LegBackLinkUnit_1"/>
    <axis xyz="-0.0 -1.0 0.0"/>
  </joint>
  <joint name="RightHipBackLink" type="continuous">
    <origin xyz="0.0 0.11 0.0" rpy="0 0 0"/>
    <parent link="ParallelLinksDriveUnit_2"/>
    <child link="LegBackLinkUnit_2"/>
    <axis xyz="0.0 -1.0 0.0"/>
  </joint>
  <joint name="LeftUpperKnee_Pitch" type="revolute">
    <origin xyz="-0.032 0.0 -0.015" rpy="0 0 0"/>
    <parent link="LegBackLinkUnit_1"/>
    <child link="LeftKneeUnit_1"/>
    <axis xyz="0.0 1.0 0.0"/>
    <limit upper="1.570796" lower="-0.523599" effort="100" velocity="100"/>
  </joint>
  <joint name="RightUpperKne_Pitch" type="revolute">
    <origin xyz="-0.032 0.0 -0.015" rpy="0 0 0"/>
    <parent link="LegBackLinkUnit_2"/>
    <child link="RightKneeUnit_1"/>
    <axis xyz="0.0 1.0 0.0"/>
    <limit upper="1.570796" lower="-0.523599" effort="100" velocity="100"/>
  </joint>
  <joint name="LeftUpperKnee_MimicPitch" type="revolute">
    <origin xyz="0.0 0.0 -0.1325" rpy="0 0 0"/>
    <parent link="LeftKneeUnit_1"/>
    <child link="LegFrontLinkUnit_1"/>
    <axis xyz="0.0 1.0 0.0"/>
    <limit upper="0.523599" lower="-1.570796" effort="100" velocity="100"/>
  </joint>
  <joint name="RightUpperKnee_MimicPitch" type="revolute">
    <origin xyz="0.0 -0.11 -0.1325" rpy="0 0 0"/>
    <parent link="RightKneeUnit_1"/>
    <child link="LegFrontLinkUnit_2"/>
    <axis xyz="0.0 1.0 0.0"/>
    <limit upper="0.523599" lower="-1.570796" effort="100" velocity="100"/>
  </joint>
  <joint name="LeftLowerKnee_Pitch" type="revolute">
    <origin xyz="0.0 0.0 -0.1325" rpy="0 0 0"/>
    <parent link="LeftKneeUnit_1"/>
    <child link="LegBackLowerLinkUnit_1"/>
    <axis xyz="0.0 1.0 0.0"/>
    <limit upper="1.570796" lower="-0.523599" effort="100" velocity="100"/>
  </joint>
  <joint name="RightLowerKnee_Pitch" type="revolute">
    <origin xyz="0.0 -0.11 -0.1325" rpy="0 0 0"/>
    <parent link="RightKneeUnit_1"/>
    <child link="LegBackLowerLinkUnit_2"/>
    <axis xyz="0.0 1.0 0.0"/>
    <limit upper="1.570796" lower="-0.523599" effort="100" velocity="100"/>
  </joint>
  <joint name="LeftLowerKnee_MimicPitch" type="revolute">
    <origin xyz="0.0 0.0 -0.1325" rpy="0 0 0"/>
    <parent link="LeftKneeUnit_1"/>
    <child link="LegFrontLowerLinkUnit_1"/>
    <axis xyz="0.0 1.0 0.0"/>
    <limit upper="0.523599" lower="-1.570796" effort="100" velocity="100"/>
  </joint>
  <joint name="RightLowerKnee_MimicPitch" type="revolute">
    <origin xyz="0.0 -0.11 -0.1325" rpy="0 0 0"/>
    <parent link="RightKneeUnit_1"/>
    <child link="LegFrontLowerLinkUnit_2"/>
    <axis xyz="0.0 1.0 0.0"/>
    <limit upper="1.570796" lower="-0.523599" effort="100" velocity="100"/>
  </joint>
  <joint name="LeftAnkle_MimicPitch" type="continuous">
    <origin xyz="0.0 0.0 -0.1575" rpy="0 0 0"/>
    <parent link="LegBackLowerLinkUnit_1"/>
    <child link="ParallelLinksDriveUnit_3"/>
    <axis xyz="0.0 1.0 0.0"/>
  </joint>
  <joint name="RightAnkle_MimicPitch" type="continuous">
    <origin xyz="0.0 0.11 -0.1575" rpy="0 0 0"/>
    <parent link="LegBackLowerLinkUnit_2"/>
    <child link="ParallelLinksDriveUnit_4"/>
    <axis xyz="0.0 1.0 0.0"/>
  </joint>
  <joint name="LeftAnkle_Pitch" type="revolute">
    <origin xyz="0.032 0.055 0.3595" rpy="0 0 0"/>
    <parent link="ParallelLinksDriveUnit_3"/>
    <child link="LegBaseUnit_2"/>
    <axis xyz="0.0 1.0 0.0"/>
    <limit upper="0.523599" lower="-1.570796" effort="100" velocity="100"/>
  </joint>
  <joint name="RightAnkle_Pitch" type="revolute">
    <origin xyz="0.032 0.0 0.305" rpy="0 0 0"/>
    <parent link="ParallelLinksDriveUnit_4"/>
    <child link="LegBaseUnit_MIR_2"/>
    <axis xyz="-0.0 1.0 -0.0"/>
    <limit upper="0.523599" lower="-1.570796" effort="100" velocity="100"/>
  </joint>
  <joint name="LeftAnkle_Roll" type="revolute">
    <origin xyz="0.0 -0.11 0.0" rpy="0 0 0"/>
    <parent link="LegBaseUnit_2"/>
    <child link="LeftFootUnit_1"/>
    <axis xyz="1.0 -0.0 0.0"/>
    <limit upper="1.047198" lower="-1.047198" effort="100" velocity="100"/>
  </joint>
  <joint name="RightAnkle_Roll" type="revolute">
    <origin xyz="0.0 -0.055 0.0545" rpy="0 0 0"/>
    <parent link="LegBaseUnit_MIR_2"/>
    <child link="RightFootUnit_1"/>
    <axis xyz="1.0 0.0 0.0"/>
    <limit upper="1.047198" lower="-1.047198" effort="100" velocity="100"/>
  </joint>
</robot>
